Workbook
Name App1Search: 'Appendix - Search & Retrieval'!$B$6:$D$6
Name App1Title: 'Appendix - Search & Retrieval'!$B$1:$E$1
Name AppChainingTitle: 'Appendix - Chaining Prompts'!$B$1:$G$1
Name AppFunctionExamples: #REF!
Name AppFunctionLesson: 'Appendix - Function Calling'!$B$8:$E$8
Name AppFunctionPlayground: #REF!
Name AppFunctionTitle: 'Appendix - Function Calling'!$B$1:$G$1
Name IntroTitle: 'Intro & Table of Contents'!$B$1:$H$1
Name QuickStartTitle: 'Tutorial How-To'!$B$1:$F$1
Name TutorialHowToTitle: #REF!
Name TutorialTitle: 'Tutorial How-To'!$B$1:$F$1

Sheet Tutorial How-To
B1: Tutorial How-To
B3: This tutorial requires an API key for interaction. If you don't have an API key, you can sign up for one via the Anthropic Console or view our static tutorial answer key instead.
B5: How to get started
B6: 1. Make a copy of this sheet and save it to your personal Google Drive 2. Install the Claude for Sheets extension (it may already be installed, in which case, skip to step 3)
D7: a. Go to the Claude for Sheets extension listing
D8: b. Click the blue install button
B11: 3. Enable use of the Claude for Sheets extension on this document:
D12: a. In the Extensions menu in the toolbar, go to Add-ons > Manage add-ons
D13: b. Click the kebab / triple dot options menu on the top right corner of the Claude for Sheets extension
D15: c. Make sure "Use in this document" is checked
B17: 4. Add your API key
D18: a. Acquire your unique Anthropic API key following these instructions
D19: b. Enable your extension by entering your API key at Extensions > Claude for Sheets™ > Enter your Anthropic API Key
B24: Usage Notes & Tips 💡
B25: This course uses Claude 3 Haiku with temperature 0. We will talk more about temperature later in the course. For now, it's enough to understand that these settings yield faster and more deterministic results. All prompt engineering techniques in this course also apply to other Claude models. To add a new line in a cell, do the following while editing a cell:
C26: Mac: Cmd + Enter
C27: Windows: Alt + Enter
B29: To navigate to other pages:
C30: 1. Click on the gray navigational links at the bottom of each page or at the top right corner of each page section
C31: 2. Click on the blue-linked pop-up
B33: When you arrive at the correct answer, Claude's response cell will turn GREEN.
B35: Feel free to make more copies of this sheet as needed.
B37: Claude model: | E37: claude-3-haiku-20240307
G39: Introduction & Table of Contents →

Sheet Claude Cache
A1: ⚠️ SHEET RESERVED FOR =CLAUDE... FUNCTIONS. DO NOT EDIT! ⚠️
A2: Key | B2: Value | C2: Expiration
A3: rywJcnr4ZQuS7qYU87K9ZtZSMmKa%8%HmjHOt3uJFb4= | B3: 1. Laura Simmons [ORGANIC FARMER] 2. Kevin Alvarez [DANCE INSTRUCTOR] 3. Rachel O'Connor [VOLUNTEER] </individuals> | C3: 2024-04-11T18:21:50.640Z
A4: ICTqpgwSnlFBH6YNJTlJZ%K5hPJidVEUgq1d6ggGToA= | B4: The career that typically requires more than a bachelor's degree between the two is social worker. While a bachelor's degree in sociology can provide a good foundation, most social worker roles require a master's degree in social work (MSW) for licensure and advanced practice. The human resources specialist role is more commonly attainable with just a bachelor's degree in sociology or a related field.</response> | C4: 2024-04-11T18:21:50.640Z
A5: WJhH%OHNVMQXQqTB03Rpp66Cqu3ItAGhum4E3+bralQ= | B5: Based on the content and tone of the email, I would classify it as a "blue" email. The email expresses confusion, uncertainty, and a request for help, which are typically associated with a "blue" emotional state or mindset. The phrases "How did I get here" and "I am not good with computer" suggest the person is feeling lost, overwhelmed, or frustrated with the situation they are in. The use of "Halp" also conveys a sense of urgency and a need for assistance, which is characteristic of a "blue" email. Overall, the email conveys a sense of distress or difficulty, which aligns more with the "blue" classification rather than the more positive and confident "green" classification. | C5: 2024-04-11T18:21:50.640Z
A6: m5Livh9wTl0WJ1mmfDnWWZRQPPTR5n5cob08fKUmOXk= | B6: Based on the content of the email, this would be classified as a "blue" email. The question about using a Mixmaster 4000 to mix paint suggests this is not a typical household task, but rather something more industrial or specialized. Blue emails generally involve more technical or work-related topics, rather than everyday personal or household matters. | C6: 2024-04-11T18:21:50.640Z
A7: !eb5ZHntwIVl7bP96oz3yxzsNTvKVV8b5qjgazkR1oo= | B7: Based on the tone and content of the email, this would be classified as a "blue" email. The email is written in all capital letters, which conveys a sense of frustration and urgency. The language used, such as "WTF is going on???" also suggests an angry or upset tone. This type of email would typically be considered a "blue" email, indicating a negative emotional state and the need for a more empathetic and understanding response. | C7: 2024-04-11T18:21:50.640Z
A8: xCJnkl%WGC2clpmNpbuw1Zw59fDobV56EvVCKL4uvec= | B8: Based on the content of the email, this would be classified as a "blue" email. The email describes a technical issue with a product, indicating a problem that needs to be addressed. This type of email is typically considered a "blue" email, as it is focused on a specific problem or request for assistance, rather than a general inquiry or positive feedback (which would be considered a "green" email). | C8: 2024-04-11T18:21:50.640Z
A9: bCmzQaGOwM9dJSv01L0ZOPQaQzxAIHx4oKB%mVYyDEQ= | B9: Hi there! How can I assist you today? | C9: 2024-04-11T18:21:50.640Z

Sheet Intro & Table of Contents
B1: Welcome to the Prompt Engineering Interactive Tutorial
B3: Course introduction and goals
B4: This course is intended to provide you with a comprehensive step-by-step understanding of how to engineer optimal prompts within Claude. After completing this course, you will be able to: ✓ Master the basic structure of a good prompt ✓ Recognize common failure modes and learn the '80/20' techniques to address them ✓ Understand Claude's strengths and weaknesses ✓ Build strong prompts from scratch for common use cases
B6: Course structure and content
B7: This course is structured to allow you many chances to practice writing and troubleshooting prompts yourself. The course is broken up into 9 chapters with accompanying exercises, as well as an appendix of even more advanced methods. It is intended for you to work through the course in chapter order. Each lesson has an "Example Playground" area at the bottom where you are free to experiment with the examples in the lesson and see for yourself how changing prompts can change Claude's responses. There is also an answer key. Note: This tutorial uses our smallest, fastest, and cheapest model, Claude 3 Haiku. We have two other models, Claude 3 Sonnet and Claude 3 Opus, which are more intelligent than Haiku, with Opus being the most intelligent. This tutorial also exists as a series of python notebooks, although we recommend using this spreadsheet as it is more user-friendly. When you are ready to begin, click on the Chapter 1 Lesson to proceed.
B9: Admin | D9: Get Started Here
E10: Tutorial How-To
B12: Beginner | D12: Chapter 1: Basic Prompt Structure
E13: Lesson
E14: Exercises
D16: Chapter 2: Being Clear and Direct
E17: Lesson
E18: Exercises
D20: Chapter 3: Assigning Roles
E21: Lesson
E22: Exercises
B24: Intermediate | D24: Chapter 4: Separating Data from Instructions
E25: Lesson
E26: Exercises
D28: Chapter 5: Formatting Output & Speaking for Claude
E29: Lesson
E30: Exercises
D32: Chapter 6: Precognition (Thinking Step by Step)
E33: Lesson
E34: Exercises
D36: Chapter 7: Using Examples
E37: Lesson
E38: Exercises
B40: Advanced | D40: Chapter 8: Avoiding Hallucinations
E41: Lesson
E42: Exercises
D44: Chapter 9: Building Complex Prompts (Industry Use Cases)
E45: Complex Prompts from Scratch - Chatbot
E46: Complex Prompts for Legal Services
E47: Exercise: Complex Prompts for Financial Services
E48: Exercise: Complex Prompts for Coding
E49: Congratulations & Next Steps
D51: Appendix: Beyond Standard Prompting
E52: Chaining Prompts
E53: Function Calling
...

Sheet 1 - Basic Prompt Structure
B1: Chapter 1: Basic Prompt Structure
B3: Page Contents
C4: Lesson
C5: Examples
C6: Example Playground
B8: Lesson | E8: Back to top ↑
B9: The Claude for Sheets extension offers several functions you can use to call Claude. One such function is CLAUDEMESSAGES(), which is built to reflect the Messages API structure.
B11: CLAUDEMESSAGES() can take several parameters, in the following order:
C12: 1. Your prompt, in quotation marks
C13: 2. The model version, in quotation marks
C14: 3. Any optional additional parameters, such as temperature, system prompt, max tokens, etc.
B15: Note: Temperature correlates to the degree of variability in Claude's answer. For these exercises, we have set the "temperature" to 0. In Chapter 8, we'll dive deeper into temperature.
B17: Anywhere in this sheet, you can call Claude by using the CLAUDEMESSAGES() formula. The basic formula is structured like this: =CLAUDEMESSAGES("{PROMPT}", "{MODEL_VERSION}", "system", "{SYSTEM_PROMPT}") For example, to call Claude 3 Haiku with a prompt located in cell A1, you would write: =CLAUDEMESSAGES(A1, "claude-3-haiku-20240307", "system", "Respond only in Esperanto")
B19: How does the CLAUDEMESSAGES() structure correlate with the Messages API structure? Let's look a few examples of prompts sent to CLAUDEMESSAGES() along with the underlying formula.
B21: Examples | E21: Back to top ↑
B22: Let's take a look at how Claude responds to some correctly-formatted prompts. Don't worry about how the answers are being generated.
C24: Prompt | E24: Claude's Response
C25: User: Hi Claude, how are you? | D25: ➤ | E25: =claudeMessages($C25,'Tutorial How-To'!$E$37,"temperature",0) -> #NAME?
C27: User: Can you tell me the color of the ocean? | D27: ➤ | E27: =claudeMessages($C27,'Tutorial How-To'!$E$37,"temperature",0) -> #NAME?
C31: User: What year was Celine Dion born in? | D31: ➤ | E31: =claudeMessages($C31,'Tutorial How-To'!$E$37,"temperature",0) -> #NAME?
B33: Now let's take a look at some prompts that do not include the correct formatting. For these malformatted prompts, the CLAUDEMESSAGES() function returns an error. Here's a prompt that's missing "User:" at the beginning.
C35: Prompt | E35: Claude's Response
C36: What year was Celine Dion born in? | D36: ➤ | E36: =claudeMessages($C36,'Tutorial How-To'!$E$37,"temperature",0) -> #NAME?
B39: Here's a prompt that fails to alternate between the User and Assistant roles.
C41: Prompt | E41: Claude's Response
C42: User: What year was Celine Dion born in? User: Also, can you tell me some other facts about her? | D42: ➤ | E42: =claudeMessages($C42,'Tutorial How-To'!$E$37,"temperature",0) -> #NAME?
B44: Here's a prompt that has too many newlines at the beginning.
C46: Prompt | E46: Claude's Response
C47: User: What year was Celine Dion born in? | D47: ➤ | E47: =claudeMessages($C47,'Tutorial How-To'!$E$37,"temperature",0) -> #NAME?
B51: "User" and "Assistant" messages MUST alternate, and messages MUST start with a "User:" turn.
B53: When using CLAUDEMESSAGES(), be sure to demarcate messages by inserting a newline between each message (a message is a single User or Assistant turn). If you fail to do so, Claude will not return an error, but Claude will consider everything not separated by a newline as part of a single message. You can have multiple "User:" / "Assistant:" pairs in a prompt (as if simulating a multi-turn conversation). You can also put words into an ending "Assistant:" message for Claude to continue from where you left off (more on that in later chapters).
B55: You can use a system prompt to give Claude instructions and guidelines. A system prompt is a way to provide context, instructions, and guidelines to Claude before presenting it with a question or task in the "User" turn. Structurally, system prompts exist separately from the list of User & Assistant messages, and thus belong in a separate "system prompt" parameter when using CLAUDEMESSAGES(). To make this easy for you in this tutorial, we've provided system prompt input boxes that feed into a complete CLAUDEMESSAGES() formula used to call Claude.
C57: System Prompt | E57: Claude's Response
C58: Your answer should always be a series of critical thinking questions that further the conversation (do not provide answers to your questions). Do not actually answer the user question. | D58: ➤ | E58: =claudeMessages($C62,'Tutorial How-To'!$E$37,"temperature",0, "system", C58) -> #NAME?
C61: Prompt
C62: User: Why is the sky blue?
B64: Why use a system prompt? A well-written system prompt can improve Claude’s performance in a variety of ways, such as increasing Claude's ability to follow rules and instructions. For more information, visit our documentation on how to use system prompts with Claude.
B66: If you're ready to try the chapter exercises, click the link below. If you want to play around with any of the examples in this lesson, scroll down!
E68: Chapter 1 Exercises: Basic Prompt Structure →
B70: Example Playground | E70: Back to top ↑
...

Sheet 1 - Exercises Basic Prompt Stru
B1: Chapter 1: Basic Prompt Structure - Exercises
B3: Page Contents
C4: Exercise 1.1 - Counting to Three
C5: Exercise 1.2 - System Prompt
B7: Exercise 1.1 - Counting to Three | E7: Back to top ↑
B8: Using proper User/Assistant formatting, write a prompt in the YELLOW cell below to get Claude to count to three.
B10: Remember, if your answer is correct (which means formatting and prompt is good), Claude's response cell will turn GREEN.
C12: Prompt | E12: Claude's Response
C13: User: [Replace this text] | D13: ➤ | E13: =claudeMessages($C13,'Tutorial How-To'!$E$37,"temperature",0) -> #NAME?
B15: ❓ | C15: If you need a hint, click on the plus sign (➕) on the far left of this row.
B16: Hint: Make sure that you include proper "User:" (and "Assistant:" if applicable) indicators in your prompt. The conditional formatting in this exercise is looking for an answer that contains the exact Arabic numerals "1" & "2" & "3".
B18: Exercise 1.2 - System Prompt | E18: Back to top ↑
B19: Modify the system prompt in the ORANGE cell to make Claude respond like it's a 3 year old child.
B21: Note: Claude's response may be much longer than it appears. To view the full response, select the response cell, then copy and paste it into a text editor.
C23: System Prompt | E23: Claude's Response
C24: [Replace this text] | D24: ➤ | E24: =claudeMessages($C27,'Tutorial How-To'!$E$37,"temperature",0, "system", C24) -> #NAME?
C26: Prompt
C27: User: How big is the sky?
B30: ❓ | C30: If you need a hint, click on the plus sign (➕) on the far left of this row.
B31: Hint: There are many ways to solve this, just by asking! The conditional formatting in this exercise is looking for answers that contain "soo" or "giggles".
B33: ← Chapter 1: Basic Prompt Structure | E33: Chapter 2: Being Clear and Direct →
B35: Back to top ↑
B36: Table of Contents

Sheet 2 - Being Clear and Direct
B1: Chapter 2: Being Clear and Direct
B3: Page Contents
C4: Lesson
C5: Examples
C6: Example Playground
B8: Lesson | E8: Back to top ↑
B9: Claude responds best to clear and direct instructions. Think of Claude like any other human that is new to the job. Claude has no context on what to do aside from what you literally tell it. Just as when you instruct a human for the first time on a task, the more you explain exactly what you want in a straightforward manner to Claude, the better and more accurate Claude's response will be.
B11: When in doubt, follow the Golden Rule of Clear Prompting: show your prompt to a colleague or friend and have them follow the instructions themselves to see if they can produce the result you want. If they're confused, Claude's confused.
B13: Examples | E13: Back to top ↑
B14: Let's take a task like writing poetry. (Ignore any syllable mismatch - LLMs aren't great at counting syllables yet.)
C16: Prompt | E16: Claude's Response
C17: User: Write a haiku about robots. | D17: ➤ | E17: =claudeMessages($C17,'Tutorial How-To'!$E$37,"temperature",0) -> #NAME?
B19: This haiku is nice enough, but users may want Claude to go directly into the poem without the "Here is a haiku" preamble. How do we achieve that? We ask for it!
C21: Prompt | E21: Claude's Response
C22: User: Write a haiku about robots. Skip the preamble; go straight into the poem. | D22: ➤ | E22: =claudeMessages($C22,'Tutorial How-To'!$E$37,"temperature",0) -> #NAME?
B24: Here's another example. Let's ask Claude who's the best basketball player of all time. You can see below that while Claude lists a few names, it doesn't respond with a definitive "best".
C26: Prompt | E26: Claude's Response
C27: User: Who is the best basketball player of all time? | D27: ➤ | E27: =claudeMessages($C27,'Tutorial How-To'!$E$37,"temperature",0) -> #NAME?
B30: Can we get Claude to make up its mind and decide on a best player? Yes! Just ask!
C32: Prompt | E32: Claude's Response
C33: User: Who is the best basketball player of all time? Yes, there are differing opinions, but if you absolutely had to pick one player, who would it be? | D33: ➤ | E33: =claudeMessages($C33,'Tutorial How-To'!$E$37,"temperature",0) -> #NAME?
B37: If you're ready to try the chapter exercises, click the link below. If you want to play around with any of the examples in this lesson, scroll down!
E39: Chapter 2 Exercises: Being Clear and Direct →
B41: Example Playground | E41: Back to top ↑
B42: This is an area for you to experiment freely with the prompt examples shown in this lesson. Feel free to tweak prompts to see how it may affect Claude's responses. Note: The colors in the cells, which have been carried over from above, will not change even if the prompt or Claude's response changes.
C44: Prompt | E44: Claude's Response
C45: User: Write a haiku about robots. | D45: ➤ | E45: =claudeMessages($C45,'Tutorial How-To'!$E$37,"temperature",0) -> #NAME?
C47: User: Write a haiku about robots. Skip the preamble; go straight into the poem. | D47: ➤ | E47: =claudeMessages($C47,'Tutorial How-To'!$E$37,"temperature",0) -> #NAME?
C49: User: Who is the best basketball player of all time? | D49: ➤ | E49: =claudeMessages($C49,'Tutorial How-To'!$E$37,"temperature",0) -> #NAME?
C52: User: Who is the best basketball player of all time? Yes, there are differing opinions, but if you absolutely had to pick one player, who would it be? | D52: ➤ | E52: =claudeMessages($C52,'Tutorial How-To'!$E$37,"temperature",0) -> #NAME?
B57: ← Chapter 1 Exercises: Basic Prompt Structure | E57: Chapter 2 Exercises: Being Clear and Direct →
B59: Back to top ↑
B60: Table of Contents

Sheet 2 - Exercises Being Clear and D
B1: Chapter 2: Being Clear and Direct - Exercises
B3: Page Contents
C4: Exercise 2.1 - Spanish
C5: Exercise 2.2 - One Player Only
C6: Exercise 2.3 - Write a Story
B8: Exercise 2.1 - Spanish | E8: Back to top ↑
B9: Adapt the system prompt in the ORANGE box to make Claude output its answer in Spanish. If your answer is correct, Claude's response cell will turn GREEN.
C11: System Prompt | E11: Claude's Response
C12: [Replace this text] | D12: ➤ | E12: =claudeMessages($C15,'Tutorial How-To'!$E$37,"temperature",0,"system",$C12) -> #NAME?
C14: Prompt
C15: User: Hello Claude, how are you?
B17: ❓ | C17: If you need a hint, click on the plus sign (➕) on the far left of this row.
B18: Hint: Ask Claude to reply in Spanish like you would when speaking with a human. It's that simple! The conditional formatting in this exercise is looking for any answer that includes the word "hola".
B20: Exercise 2.2 - One Player Only | E20: Back to top ↑
B21: Modify the basketball player prompt in the YELLOW prompt box so that Claude doesn't equivocate at all and responds with ONLY the name of one specific player, with no other words or punctuation. If your answer is correct, Claude's response cell will turn GREEN.
C23: Prompt | E23: Claude's Response
C24: User: Who is the best basketball player of all time? | D24: ➤ | E24: =claudeMessages($C24,'Tutorial How-To'!$E$37,"temperature",0) -> #NAME?
B28: ❓ | C28: If you need a hint, click on the plus sign (➕) on the far left of this row.
B29: Hint: How would you ask another human to do this? Reply with no other words? Reply with only the name and nothing else? There are several ways to approach this answer. The conditional formatting in this exercise is looking for exactly "Michael Jordan".
B31: Exercise 2.3 - Write a Story | E31: Back to top ↑
B32: Modify the prompt in the YELLOW prompt box so that Claude responds with as long a response as you can muster. If your answer is over 800 words, Claude's response cell will turn GREEN. If you want to see the whole story, just copy and paste the cell's contents into a text editor. Note: If you did your job well, it will be "Loading" its response for a while, as the time Claude takes to respond is largely proportional to the number of output tokens.
C34: Prompt | E34: Claude's Response
C35: User: Can you write me a story? | D35: ➤ | E35: =claudeMessages($C35,'Tutorial How-To'!$E$37,"temperature",0, "max_tokens_to_sample", 4000) -> #NAME?
B40: ❓ | C40: If you need a hint, click on the plus sign (➕) on the far left of this row.
B41: Hint: Because LLMs aren't great at counting words yet, you may have to overshoot your target. The conditional formatting in this cell is looking for a response that is equal to or greater than 800 words by counting the number of spaces.
B43: ← Chapter 2: Being Clear and Direct | E43: Chapter 3: Assigning Roles (Role Prompting) →
B45: Back to top ↑
B46: Table of Contents

Sheet 3 - Assigning Roles (Role Promp
B1: Chapter 3: Assigning Roles (Role Prompting)
B3: Page Contents
C4: Lesson
C5: Examples
C6: Example Playground
B8: Lesson | E8: Back to top ↑
B9: Continuing on the theme of Claude having no context aside from what you say, it's sometimes important to prompt Claude to inhabit a specific role (including all necessary context). This is also known as role prompting. The more detail to the role context, the better. Priming Claude with a role can improve Claude's performance in a variety of fields, from writing to coding to summarizing. It's like how humans can sometimes be helped when told to "think like a ______". Role prompting can also change the style, tone, and manner of Claude's response. Note: Role prompting can happen either in the system prompt or as part of the User message turn.
B11: Examples | E11: Back to top ↑
B12: In the example below, we see that without role prompting, Claude provides a straightforward and non-stylized answer when asked to give a single sentence perspective on skateboarding. However, when we prime Claude to inhabit the role of a cat, Claude's perspective changes, and thus Claude's response tone, style, content adapts to the new role. Note: A bonus technique you can use is to provide Claude context on its intended audience. Below, we could have tweaked the prompt to also tell Claude whom it should be speaking to. "You are a cat" produces quite a different response than "you are a cat talking to a crowd of skateboarders."
C14: System Prompt (without Role Prompting) | E14: Claude's Response
D15: ➤ | E15: =claudeMessages($C18,'Tutorial How-To'!$E$37,"temperature",0,"system",$C15) -> #NAME?
C17: Prompt
C18: User: In one sentence, what do you think about skateboarding?
B21: Here is the same user question, except with role prompting.
C23: System Prompt (with Role Prompting) | E23: Claude's Response
C24: You are a cat. | D24: ➤ | E24: =claudeMessages($C27,'Tutorial How-To'!$E$37,"temperature",0,"system",$C24) -> #NAME?
C26: Prompt
C27: User: In one sentence, what do you think about skateboarding?
B29: You can use role prompting as a way to get Claude to emulate certain styles in writing, speak in a certain voice, or guide the complexity of its answers. Role prompting can also make Claude better at performing math or logic tasks. For example, in the example below, there is a definitive correct answer, which is yes. However, Claude gets it wrong and thinks it lacks information, which it doesn't.
C31: System Prompt (without Role Prompting) | E31: Claude's Response
D32: ➤ | E32: =claudeMessages($C35,'Tutorial How-To'!$E$37,"temperature",0,"system",$C32) -> #NAME?
C34: Prompt
C35: User: Jack is looking at Anne. Anne is looking at George. Jack is married, George is not, and we don’t know if Anne is married. Is a married person looking at an unmarried person?
B37: Now, what if we prime Claude to act as a logic bot? How will that change Claude's answer? It turns out that with this new role assignment, Claude gets it right. (Although notably not for all the right reasons)
C39: System Prompt (with Role Prompting) | E39: Claude's Response
C40: You are a logic bot designed to answer complex logic problems. | D40: ➤ | E40: =claudeMessages($C43,'Tutorial How-To'!$E$37,"temperature",0,"system",$C40) -> #NAME?
C42: Prompt
C43: User: Jack is looking at Anne. Anne is looking at George. Jack is married, George is not, and we don’t know if Anne is married. Is a married person looking at an unmarried person?
B45: Note: What you'll learn throughout this course is that there are many prompt engineering techniques you can use to derive similar results. Which techniques you use is up to you and your preference! We encourage you to experiment to find your own prompt engineering style.
B47: If you're ready to try the chapter exercises, click the link below. If you want to play around with any of the examples in this lesson, scroll down!
E49: Chapter 3 Exercises: Assigning Roles →
B51: Example Playground | E51: Back to top ↑
B52: This is an area for you to experiment freely with the prompt examples shown in this lesson. Feel free to tweak prompts to see how it may affect Claude's responses. Note: The colors in the cells, which have been carried over from above, will not change even if the prompt or Claude's response changes.
C54: System Prompt (without Role Prompting) | E54: Claude's Response
D55: ➤ | E55: =claudeMessages($C58,'Tutorial How-To'!$E$37,"temperature",0,"system",$C55) -> #NAME?
C57: Prompt
C58: User: In one sentence, what do you think about skateboarding?
C60: System Prompt (with Role Prompting) | E60: Claude's Response
C61: You are a cat. | D61: ➤ | E61: =claudeMessages($C64,'Tutorial How-To'!$E$37,"temperature",0,"system",$C61) -> #NAME?
C63: Prompt
...

Sheet 3 - Exercises Assigning Roles (
B1: Chapter 3: Assigning Roles - Exercises
B3: Page Contents
C4: Exercise 3.1 - Math Correction
B6: Exercise 3.1 - Math Correction | E6: Back to top ↑
B7: In some instances, Claude may struggle with mathematics, even simple mathematics. Below, Claude incorrectly assesses the math problem as correctly solved, even though there's an obvious arithmetic mistake in the second step. Note that Claude actually catches the mistake when going through step-by-step, but doesn't jump to the conclusion that the overall solution is wrong. Adapt the text in the YELLOW prompt box and / or the ORANGE system prompt box to make Claude grade the solution as incorrectly solved, rather than correctly solved. If your answer is correct, Claude's response cell will turn GREEN.
C9: System Prompt | E9: Claude's Response
D10: ➤ | E10: =claudeMessages($C13,'Tutorial How-To'!$E$37,"system",$C10,"temperature",0) -> #NAME?
C12: Prompt
C13: User: Is this equation solved correctly below? 2x - 3 = 9 2x = 6 x = 3
B15: ❓ | C15: If you need a hint, click on the plus sign (➕) on the far left of this row.
B16: Hint: Give Claude a role that might make Claude better at solving math problems! Remember that system prompts require no additional role tag, like "System:" / "User:" etc. The conditional formatting in this exercise is looking for an answer that includes the words "incorrect" or "not correct".
B18: ← Chapter 3: Assigning Roles | E18: Chapter 4: Separating Data and Instructions →
B20: Back to top ↑
B21: Table of Contents

Sheet 4 - Separating Data and Instruc
B1: Chapter 4: Separating Data from Instructions
B3: Page Contents
C4: Lesson
C5: Examples
C6: Example Playground
B8: Lesson | I8: Back to top ↑
B9: Oftentimes, we don't want to write full prompts, but instead want prompt templates that can be modified later with additional input data before submitting to Claude. This might come in handy if you want Claude to do the same thing every time, but the data that Claude uses for its task might be different each time. Luckily, we can do this pretty easily by separating the fixed skeleton of the prompt from variable user input, then substituting the user input into the prompt before sending the full prompt to Claude. Below, we'll walk step by step through how to write a substitutable prompt template, as well as how to substitute in user input.
B11: Examples | I11: Back to top ↑
B12: In this first example, we're asking Claude to act as an animal noise generator. Notice that the full prompt submitted to Claude (the YELLOW third box in the chain) is just the prompt template (first box) substituted with the input (in this case, "Cow", in the second box). Notice that the word "Cow" replaces "{{ANIMAL}}" in the yellow third box. Note: You don't have to call your substitution placeholder anything in particular in practice. For this example, definitely use {{ANIMAL}}, as that's how the exercise is formatted. But in general, just as easily, we could have called it "{{CREATURE}}" or "{{A}}" (but it's generally good to have your stand-ins be specific and relevant so that your prompt is easy to understand even without the substitution, just for user parseability). Just make sure that whatever you name your substitution placeholder is what you use for the substitution formula.
C14: Prompt Template | E14: Input {{ANIMAL}} | G14: Prompt After Substitution | I14: Claude's Response
C15: User: I will tell you the name of an animal. Please respond with the noise that animal makes. {{ANIMAL}} | D15: ﹢ | E15: Cow | F15: ＝ | G15: =SUBSTITUTE(C15,"{{ANIMAL}}",E15) -> User: I will tell you the name of an animal. Please respond with the noise that animal makes. Cow | H15: ➤ | I15: =claudeMessages($G15,'Tutorial How-To'!$E$37,"temperature",0) -> #NAME?
B17: Why would we want to separate and substitute inputs like this? Well, prompt templates simplify repetitive tasks. Let's say you build a prompt structure that invites third party users to submit content to the prompt (in this case the animal whose sound they want to generate). These third party users don't have to write or even see the full prompt. All they have to do is fill in variables. We do this substitution here using spreadsheet functions, but this is a best practice for coding as well! We use the {{double-curly-brackets}} formatting in our own code. Note: Prompt templates can have as many variables as desired.
B19: When introducing substitution variables like this, it is very important to make sure Claude knows where variables start and end (vs. instructions or task descriptions). Let's look at an example where there is no separation between the instructions and the substitution variable.
C21: Prompt Template | E21: Input {{EMAIL}} | G21: Prompt After Substitution | I21: Claude's Response
C22: User: Yo Claude. {{EMAIL}} <----- Make this email more polite but don't change anything else about it. | D22: ﹢ | E22: Show up at 6am tomorrow because I'm the CEO and I say so. | F22: ＝ | G22: =SUBSTITUTE(C22,"{{EMAIL}}",E22) -> User: Yo Claude. Show up at 6am tomorrow because I'm the CEO and I say so. <----- Make this email more polite but don't change anything else about it. | H22: ➤ | I22: =claudeMessages($G22,'Tutorial How-To'!$E$37,"temperature",0) -> #NAME?
B28: Here, Claude thinks "Yo Claude" is part of the email it's supposed to rewrite! You can tell because it begins its rewrite with "Dear Claude". To the human eye, it's clear, particularly in the prompt template where the email begins and ends, but it becomes much less clear in the prompt after substitution.
B30: How do we solve this? Wrap the input in XML tags! We did this below, and as you can see, there's no more "Dear Claude" in the output. XML tags are angle-bracket tags like <tag></tag>. They come in pairs and consist of an opening tag, such as <tag>, and a closing tag marked by a "/", such as </tag>. XML tags are used to wrap around content, like this: <tag>content</tag>. Note: While Claude can recognize and work with a wide range of separators and delimeters, we recommend that you use specifically XML tags as separators for Claude, as Claude was trained specifically to recognize XML tags as a prompt organizing mechanism. Outside of function calling, there are no special sauce XML tags that Claude has been trained on that you should use to maximally boost your performance. We have purposefully made Claude very malleable and customizable this way.
C32: Prompt Template | E32: Input {{EMAIL}} | G32: Prompt After Substitution | I32: Claude's Response
C33: User: Yo Claude. <email>{{EMAIL}}</email> <----- Make this email more polite but don't change anything else about it. | D33: ﹢ | E33: Show up at 6am because I'm the CEO and I say so. | F33: ＝ | G33: =SUBSTITUTE(C33,"{{EMAIL}}",E33) -> User: Yo Claude. <email>Show up at 6am because I'm the CEO and I say so.</email> <----- Make this email more polite but don't change anything else about it. | H33: ➤ | I33: =claudeMessages($G33,'Tutorial How-To'!$E$37,"temperature",0) -> #NAME?
B38: Let's see another example of how XML tags can help us. In the following prompt, Claude incorrectly interprets what part of the prompt is the instruction vs. the input. It incorrectly considers "Each is about an animal, like rabbits" to be part of the list due to the formatting, when the user (the one filling out the {{SENTENCES}} variable) presumably did not want that.
C40: Prompt Template | E40: Input {{SENTENCES}} | G40: Prompt After Substitution | I40: Claude's Response
C41: User: Below is a list of sentences. Tell me the second item on the list. - Each is about an animal, like rabbits. {{SENTENCES}} | D41: ﹢ | E41: - I like how cows sound - This sentence is about spiders - This sentence may appear to be about dogs but it's actually about pigs | F41: ＝ | G41: =SUBSTITUTE(C41,"{{SENTENCES}}",E41) -> User: Below is a list of sentences. Tell me the second item on the list. - Each is about an animal, like rabbits. - I like how cows sound - This sentence is about spiders - This sentence may appear to be about dogs but it's actually about pigs | H41: ➤ | I41: =claudeMessages($G41,'Tutorial How-To'!$E$37,"temperature",0) -> #NAME?
B44: To fix this, we just need to surround the user input sentences in XML tags. This shows Claude where the input data begins and ends despite the misleading hyphen before "Each is about an animal, like rabbits."
C46: Prompt Template | E46: Input {{SENTENCES}} | G46: Prompt After Substitution | I46: Claude's Response
C47: User: Below is a list of sentences. Tell me the second item on the list. - Each is about an animal, like rabbits. <sentences> {{SENTENCES}} </sentences> | D47: ﹢ | E47: - I like how cows sound - This sentence is about spiders - This sentence may appear to be about dogs but it's actually about pigs | F47: ＝ | G47: =SUBSTITUTE(C47,"{{SENTENCES}}",E47) -> User: Below is a list of sentences. Tell me the second item on the list. - Each is about an animal, like rabbits. <sentences> - I like how cows sound - This sentence is about spiders - This sentence may appear to be about dogs but it's actually about pigs </sentences> | H47: ➤ | I47: =claudeMessages($G47,'Tutorial How-To'!$E$37,"temperature",0) -> #NAME?
B51: Note: In the incorrect version of the "Each is about an animal" prompt, we had to include the hyphen to get Claude to respond incorrectly in the way we wanted to for this example. This is an important lesson about prompting: small details matter! It's always worth it to scrub your prompts for typos and grammatical errors. Claude is sensitive to patterns (in its early years, before finetuning, it was a raw text-prediction tool), and it's more likely to make mistakes when you make mistakes, smarter when you sound smart, sillier when you sound silly, and so on.
B53: If you're ready to try the chapter exercises, click the link below. If you want to play around with any of the examples in this lesson, scroll down!
I55: Chapter 4 Exercises: Separating Data from Instructions →
B57: Example Playground | I57: Back to top ↑
B58: This is an area for you to experiment freely with the prompt examples shown in this lesson. Feel free to tweak prompts to see how it may affect Claude's responses. Note: The colors in the cells, which have been carried over from above, will not change even if the prompt or Claude's response changes.
C60: Prompt Template | E60: Input {{ANIMAL}} | G60: Prompt After Substitution | I60: Claude's Response
C61: User: I will tell you the name of an animal. Please respond with the noise that animal makes. {{ANIMAL}} | D61: ﹢ | E61: Cow | F61: ＝ | G61: =SUBSTITUTE(C61,"{{ANIMAL}}",E61) -> User: I will tell you the name of an animal. Please respond with the noise that animal makes. Cow | H61: ➤ | I61: =claudeMessages($G61,'Tutorial How-To'!$E$37,"temperature",0) -> #NAME?
C63: Prompt Template | E63: Input {{EMAIL}} | G63: Prompt After Substitution | I63: Claude's Response
C64: User: Yo Claude. {{EMAIL}} <----- Make this email more polite but don't change anything else about it. | D64: ﹢ | E64: Show up at 6am tomorrow because I'm the CEO and I say so. | F64: ＝ | G64: =SUBSTITUTE(C64,"{{EMAIL}}",E64) -> User: Yo Claude. Show up at 6am tomorrow because I'm the CEO and I say so. <----- Make this email more polite but don't change anything else about it. | H64: ➤ | I64: =claudeMessages($G64,'Tutorial How-To'!$E$37,"temperature",0) -> #NAME?
C70: Prompt Template | E70: Input {{EMAIL}} | G70: Prompt After Substitution | I70: Claude's Response
C71: User: Yo Claude. <email>{{EMAIL}}</email> <----- Make this email more polite but don't change anything else about it. | D71: ﹢ | E71: Show up at 6am because I'm the CEO and I say so. | F71: ＝ | G71: =SUBSTITUTE(C71,"{{EMAIL}}",E71) -> User: Yo Claude. <email>Show up at 6am because I'm the CEO and I say so.</email> <----- Make this email more polite but don't change anything else about it. | H71: ➤ | I71: =claudeMessages($G71,'Tutorial How-To'!$E$37,"temperature",0) -> #NAME?
C76: Prompt Template | E76: Input {{SENTENCES}} | G76: Prompt After Substitution | I76: Claude's Response
C77: User: Below is a list of sentences. Tell me the second item on the list. - Each is about an animal, like rabbits. {{SENTENCES}} | D77: ﹢ | E77: - I like how cows sound - This sentence is about spiders - This sentence may appear to be about dogs but it's actually about pigs | F77: ＝ | G77: =SUBSTITUTE(C77,"{{SENTENCES}}",E77) -> User: Below is a list of sentences. Tell me the second item on the list. - Each is about an animal, like rabbits. - I like how cows sound - This sentence is about spiders - This sentence may appear to be about dogs but it's actually about pigs | H77: ➤ | I77: =claudeMessages($G77,'Tutorial How-To'!$E$37,"temperature",0) -> #NAME?
C80: Prompt Template | E80: Input {{SENTENCES}} | G80: Prompt After Substitution | I80: Claude's Response
C81: User: Below is a list of sentences. Tell me the second item on the list. - Each is about an animal, like rabbits. <sentences> {{SENTENCES}} </sentences> | D81: ﹢ | E81: - I like how cows sound - This sentence is about spiders - This sentence may appear to be about dogs but it's actually about pigs | F81: ＝ | G81: =SUBSTITUTE(C81,"{{SENTENCES}}",E81) -> User: Below is a list of sentences. Tell me the second item on the list. - Each is about an animal, like rabbits. <sentences> - I like how cows sound - This sentence is about spiders - This sentence may appear to be about dogs but it's actually about pigs </sentences> | H81: ➤ | I81: =claudeMessages($G81,'Tutorial How-To'!$E$37,"temperature",0) -> #NAME?
...

Sheet 4 - Exercises Separating Data a
B1: Chapter 4: Separating Data from Instructions - Exercises
B3: Page Contents
C4: Exercise 4.1 - Haiku Topic
C5: Exercise 4.2 - Dog Question with Typos
C6: Exercise 4.3 - Dog Question Part 2
B8: Exercise 4.1 - Haiku Topic | I8: Back to top ↑
B9: Write a prompt in the highlighted template box that will take in a variable called "{{TOPIC}}" and output a haiku about the topic. This exercise is just meant to test your understanding of the variable templating structure.
C11: Prompt Template | E11: Input {{TOPIC}} | G11: Prompt After Substitution | I11: Claude's Response
D12: ﹢ | E12: Pigs | F12: ＝ | G12: =SUBSTITUTE(C12,"{{TOPIC}}",E12) | H12: ➤ | I12: =claudeMessages(G12, 'Tutorial How-To'!E37,"temperature",0) -> #NAME?
B14: ❓ | C14: If you need a hint, click on the plus sign (➕) on the far left of this row.
B15: Hint: Don't forget to include "User:" at the start of your message list, as well as the exact phrase "{{TOPIC}}" wherever you want the topic to be substituted in. Changing the input cell (E12) should make Claude write a haiku about a different topic. The conditional formatting in this exercise is looking for a solution that includes the words "haiku" and "pig".
B17: Exercise 4.2 - Dog Question with Typos | I17: Back to top ↑
B18: Fix the prompt in the highlighted template box by adding XML tags so that Claude produces the right answer. Try not to change anything else about the prompt. The messy and mistake-ridden writing is intentional, so you can see how Claude reacts to such mistakes. Claude's response will turn GREEN if your prompt produces the right answer.
B20: Note: Although Claude can somewhat parse through broken prompts with poor grammar and misspelled words, having a clearly written, spell-checked and grammatically correct prompt far decreases the risk of Claude making mistakes and far increases the quality of Claude's output.
C22: Prompt Template | E22: Input {{QUESTION}} | G22: Prompt After Substitution | I22: Claude's Response
C23: User: Hia its me i have a q about dogs jkaerjv {{QUESTION}} jklmvca tx it help me muhch much atx fst fst answer short short tx | D23: ﹢ | E23: ar cn brown? | F23: ＝ | G23: =SUBSTITUTE(C23,"{{QUESTION}}",E23) -> User: Hia its me i have a q about dogs jkaerjv ar cn brown? jklmvca tx it help me muhch much atx fst fst answer short short tx | H23: ➤ | I23: =claudeMessages(G23, 'Tutorial How-To'!E37,"temperature",0) -> #NAME?
B25: ❓ | C25: If you need a hint, click on the plus sign (➕) on the far left of this row.
B26: Hint: If you surround "{{QUESTION}}" in XML tags, how does that change Claude's response? The conditional formatting in this exercise is looking for a response that includes the word "brown".
B28: Exercise 4.3 - Dog Question Part 2 | I28: Back to top ↑
B29: Fix the prompt in the highlighted template box WITHOUT adding XML tags. Instead, remove only one or two words from the prompt. Just as with the above exercises, try not to change anything else about the prompt. This will show you what kind of language Claude can parse and understand. Claude's response will turn GREEN if your prompt produces the right answer.
C31: Prompt Template | E31: Input {{QUESTION}} | G31: Prompt After Substitution | I31: Claude's Response
C32: User: Hia its me i have a q about dogs jkaerjv {{QUESTION}} jklmvca tx it help me muhch much atx fst fst answer short short tx | D32: ﹢ | E32: ar cn brown? | F32: ＝ | G32: =SUBSTITUTE(C32,"{{QUESTION}}",E32) -> User: Hia its me i have a q about dogs jkaerjv ar cn brown? jklmvca tx it help me muhch much atx fst fst answer short short tx | H32: ➤ | I32: =claudeMessages(G32, 'Tutorial How-To'!E37,"temperature",0) -> #NAME?
B34: ❓ | C34: If you need a hint, click on the plus sign (➕) on the far left of this row.
B35: Hint: Try removing one word or section of characters at a time, starting with the parts that make the least sense. Doing this one word at a time will also help you see just how much Claude can or can't parse and understand. The conditional formatting in this exercise is looking for a response that includes the word "brown".
B37: ← Chapter 4: Separating Data from Instructions | I37: Chapter 5: Formatting Output & Speaking for Claude →
B39: Back to top ↑
B40: Table of Contents

Sheet 5 - Formatting Output & Speakin
B1: Chapter 5: Formatting Output & Speaking for Claude
B3: Page Contents
C4: Lesson
C5: Examples
C6: Example Playground
B8: Lesson | I8: Back to top ↑
B9: Claude can format its output in a wide variety of ways. You just need to ask for it to do so! One of these ways is by using XML tags to separate out the response from any other superfluous text. You've already learned that you can use XML tags to make your prompt clearer and more parseable to Claude. It turns out, you can also ask Claude to use XML tags to make its output clearer and more easily understandable to humans.
B11: Examples | I11: Back to top ↑
B12: Remember the 'poem preamble problem' we solved in Chapter 2 by asking Claude to skip the preamble entirely? It turns out we can also achieve a similar outcome by telling Claude to put the poem in XML tags.
C14: Prompt Template | E14: Input {{ANIMAL}} | G14: Prompt After Substitution | I14: Claude's Response
C15: User: Please write a haiku about {{ANIMAL}}. Put it in <haiku> tags. | D15: ﹢ | E15: Rabbit | F15: ＝ | G15: =SUBSTITUTE(C15,"{{ANIMAL}}",E15) -> User: Please write a haiku about Rabbit. Put it in <haiku> tags. | H15: ➤ | I15: =claudeMessages($G15,'Tutorial How-To'!$E$37,"temperature",0) -> #NAME?
B17: Why is this something we'd want to do? Well, having the output in XML tags allows the end user to reliably get the poem and only the poem by writing a short program to extract the content between XML tags.
B19: An extension of this technique is to put the first XML tag AFTER "Assistant:". When you put text after "Assistant:", you're basically telling Claude that Claude has already said something, and that it should continue from that point onward. This technique is called "speaking for Claude" or "prefilling Claude's response." Below, we've done this with the first <haiku> XML tag. Notice how Claude continues directly from where we left off.
C21: Prompt Template | E21: Input {{ANIMAL}} | G21: Prompt After Substitution | I21: Claude's Response
C22: User: Please write a haiku about {{ANIMAL}}. Put it in <haiku> tags. Assistant: <haiku> | D22: ﹢ | E22: Cat | F22: ＝ | G22: =SUBSTITUTE(C22,"{{ANIMAL}}",E22) -> User: Please write a haiku about Cat. Put it in <haiku> tags. Assistant: <haiku> | H22: ➤ | I22: =claudeMessages($G22,'Tutorial How-To'!$E$37,"temperature",0) -> #NAME?
B24: Claude also excels at using other output formatting styles, notably JSON. If you want to enforce JSON output (not deterministically, but close to it), you can also prefill Claude's response with the opening bracket, "{".
C26: Prompt Template | E26: Input {{ANIMAL}} | G26: Prompt After Substitution | I26: Claude's Response
C27: User: Please write a haiku about {{ANIMAL}}. Use JSON format with the keys as "first_line", "second_line", and "third_line". Assistant: { | D27: ﹢ | E27: Cat | F27: ＝ | G27: =SUBSTITUTE(C27,"{{ANIMAL}}",E27) -> User: Please write a haiku about Cat. Use JSON format with the keys as "first_line", "second_line", and "third_line". Assistant: { | H27: ➤ | I27: =claudeMessages($G27,'Tutorial How-To'!$E$37,"temperature",0) -> #NAME?
B29: Below is an example of multiple input variables in the same prompt AND output formatting specification, all done using XML tags.
C31: Prompt Template | E31: Input {{EMAIL}} | G31: Prompt After Substitution | I31: Claude's Response
C32: User: Hey Claude. Here is an email: <email>{{EMAIL}}</email>. Make this email more {{ADJECTIVE}}. Write the new version in <{{ADJECTIVE}}_email> XML tags. Assistant: <{{ADJECTIVE}}_email> | D32: ﹢ | E32: Hi Zack, just pinging you for a quick update on that prompt you were supposed to write. | F32: ＝ | G32: =SUBSTITUTE(SUBSTITUTE(C32,"{{EMAIL}}",E32),"{{ADJECTIVE}}",E35) -> User: Hey Claude. Here is an email: <email>Hi Zack, just pinging you for a quick update on that prompt you were supposed to write.</email>. Make this email more olde english. Write the new version in <olde english_email> XML tags. Assistant: <olde english_email> | H32: ➤ | I32: =claudeMessages($G32,'Tutorial How-To'!$E$37,"temperature",0) -> #NAME?
E34: Input {{ADJECTIVE}}
D35: ﹢ | E35: olde english
B37: Bonus lesson: To learn more about controlling Claude's output using the API, click on the plus sign (➕) on the far left of this row!
B38: If you are calling Claude through the API, you can pass the closing XML tag to the "stop_sequences" parameter to get Claude to stop sampling once it emits your desired tag. This can save money and time-to-last-token by eliminating Claude's concluding remarks after it's already given you the answer you care about.
B40: If you're ready to try the chapter exercises, click the link below. If you want to play around with any of the examples in this lesson, scroll down!
I42: Chapter 5 Exercises: Formatting Output & Speaking for Claude →
B44: Example Playground | I44: Back to top ↑
B45: This is an area for you to experiment freely with the prompt examples shown in this lesson. Feel free to tweak prompts to see how it may affect Claude's responses. Note: The colors in the cells, which have been carried over from above, will not change even if the prompt or Claude's response changes.
C47: Prompt Template | E47: Input {{ANIMAL}} | G47: Prompt After Substitution | I47: Claude's Response
C48: User: Please write a haiku about {{ANIMAL}}. Put it in <haiku> tags. | D48: ﹢ | E48: Rabbit | F48: ＝ | G48: =SUBSTITUTE(C48,"{{ANIMAL}}",E48) -> User: Please write a haiku about Rabbit. Put it in <haiku> tags. | H48: ➤ | I48: =claudeMessages($G48,'Tutorial How-To'!$E$37,"temperature",0) -> #NAME?
C50: Prompt Template | E50: Input {{ANIMAL}} | G50: Prompt After Substitution | I50: Claude's Response
C51: User: Please write a haiku about {{ANIMAL}}. Put it in <haiku> tags. Assistant: <haiku> | D51: ﹢ | E51: Cat | F51: ＝ | G51: =SUBSTITUTE(C51,"{{ANIMAL}}",E51) -> User: Please write a haiku about Cat. Put it in <haiku> tags. Assistant: <haiku> | H51: ➤ | I51: =claudeMessages($G51,'Tutorial How-To'!$E$37,"temperature",0) -> #NAME?
C53: Prompt Template | E53: Input {{ANIMAL}} | G53: Prompt After Substitution | I53: Claude's Response
C54: User: Please write a haiku about {{ANIMAL}}. Use JSON format with the keys as "first_line", "second_line", and "third_line". Assistant: { | D54: ﹢ | E54: Cat | F54: ＝ | G54: =SUBSTITUTE(C54,"{{ANIMAL}}",E54) -> User: Please write a haiku about Cat. Use JSON format with the keys as "first_line", "second_line", and "third_line". Assistant: { | H54: ➤ | I54: =claudeMessages($G54,'Tutorial How-To'!$E$37,"temperature",0) -> #NAME?
C56: Prompt Template | E56: Input {{EMAIL}} | G56: Prompt After Substitution | I56: Claude's Response
C57: User: Hey Claude. Here is an email: <email>{{EMAIL}}</email>. Make this email more {{ADJECTIVE}}. Write the new version in <{{ADJECTIVE}}_email> XML tags. Assistant: <{{ADJECTIVE}}_email> | D57: ﹢ | E57: Hi Zack, just pinging you for a quick update on that prompt you were supposed to write. | F57: ＝ | G57: =SUBSTITUTE(SUBSTITUTE(C57,"{{EMAIL}}",E57),"{{ADJECTIVE}}",E60) -> User: Hey Claude. Here is an email: <email>Hi Zack, just pinging you for a quick update on that prompt you were supposed to write.</email>. Make this email more olde english. Write the new version in <olde english_email> XML tags. Assistant: <olde english_email> | H57: ➤ | I57: =claudeMessages($G57,'Tutorial How-To'!$E$37,"temperature",0) -> #NAME?
E59: Input {{ADJECTIVE}}
D60: ﹢ | E60: olde english
B63: ← Chapter 4 Exercises: Separating Data and Instructions | I63: Chapter 5 Exercises: Formatting Output & Speaking for Claude →
...

Sheet 5 - Exercises Formatting Output
B1: Chapter 5: Formatting Output & Speaking for Claude - Exercises
B3: Page Contents
C4: Exercise 5.1 - Steph Curry GOAT
C5: Exercise 5.2 - Two Haikus
C6: Exercise 5.3 - Two Haikus, Two Animals
B8: Exercise 5.1 - Steph Curry GOAT | I8: Back to top ↑
B9: Forced to make a choice, Claude designates Michael Jordan as the best basketball player of all time. Can we get Claude to pick someone else? Modify the "best basketball player" prompt in the highlighted template box and use the "speaking for Claude" technique (putting words after "Assistant:") to compell Claude to make a detailed argument that the best basketball player of all time is Stephen Curry. Claude's response will turn GREEN if your prompt produces the right answer.
C11: Prompt Template | G11: Claude's Response
C12: User: Who is the best basketball player of all time? Please choose one specific player. Assistant: | F12: ＝ | G12: =claudeMessages(C12, 'Tutorial How-To'!$E$37,"temperature",0) -> #NAME?
B16: ❓ | C16: If you need a hint, click on the plus sign (➕) on the far left of this row.
B17: Hint: Write more words in Claude's voice to steer Claude to act the way you want it to. For instance, instead of "Stephen Curry is the best because," you could write "Stephen Curry is the best and here are three reasons why. 1:" The conditional formatting for this exercise is looking for a response that includes the word "Warrior".
B19: Exercise 5.2 - Two Haikus | I19: Back to top ↑
B20: Modify the haiku prompt in the highlighted template box below and use XML tags so that Claude writes two haikus about the animal instead of just one. It should be clear where one poem ends and the other begins. Claude's response will turn GREEN if your prompt produces the right answer.
C22: Prompt Template | E22: Input {{ANIMAL}} | G22: Prompt After Substitution | I22: Claude's Response
C23: User: Please write a haiku about {{ANIMAL}}. Put it in <haiku> tags. Assistant: <haiku> | D23: ﹢ | E23: cats | F23: ＝ | G23: =SUBSTITUTE(C23,"{{ANIMAL}}",E23) -> User: Please write a haiku about cats. Put it in <haiku> tags. Assistant: <haiku> | H23: ➤ | I23: =claudeMessages(G23, 'Tutorial How-To'!$E$37,"temperature",0) -> #NAME?
B26: ❓ | C26: If you need a hint, click on the plus sign (➕) on the far left of this row.
B27: Hint: Start simple. Currently, the prompt asks Claude for one haiku. You can change that and ask for two (or even more). Then if you run into formatting issues, change your prompt to fix that after you've already gotten Claude to write more than one haiku. The conditional formatting looks for a response of over 5 lines in length that includes the words "cat" and "<haiku>".
B29: Exercise 5.3 - Two Haikus, Two Animals | I29: Back to top ↑
B30: Modify the haiku prompt in the highlighted template box below so that Claude produces two haikus about two different animals. Use {{ANIMAL1}} as a stand-in for the first substitution, and {{ANIMAL2}} as a stand-in for the second substitution. Claude's response will turn GREEN if your prompt produces the right answer.
C32: Prompt Template | E32: Input {{ANIMAL1}} | G32: Prompt After Substitution | I32: Claude's Response
C33: User: Please write a haiku about {{ANIMAL1}}. Put it in <haiku> tags. | D33: ﹢ | E33: Cat | F33: ＝ | G33: =SUBSTITUTE(SUBSTITUTE(C33,"{{ANIMAL1}}",E33),"{{ANIMAL2}}",E36) -> User: Please write a haiku about Cat. Put it in <haiku> tags. | H33: ➤ | I33: =claudeMessages(G33, 'Tutorial How-To'!$E$37,"temperature",0) -> #NAME?
E35: Input {{ANIMAL2}}
D36: ﹢ | E36: Dog
B38: ❓ | C38: If you need a hint, click on the plus sign (➕) on the far left of this row.
B39: Hint: It's helpful to break this exercise down to several steps.
B40: 1. | C40: Modify the initial prompt template so that Claude writes two poems.
B41: 2. | C41: Give Claude indicators as to what the poems will be about, but instead of writing in the subjects directly (e.g., dog, cat, etc.), replace those subjects with the keywords "{{ANIMAL1}}" and "{{ANIMAL2}}".
B42: 3. | C42: Check to make sure the "Prompt After Substitution" box has all the words correctly substituted. If not, check to make sure your {{bracket}} tags are spelled correctly with the exact formatting given.
B43: The conditional formatting in this exercise is looking for a response that contains the words "tail", "cat", and "<haiku>".
B45: ← Chapter 5: Formatting Output & Speaking for Claude | H45: Chapter 6: Precognition (Thinking Step by Step) →
B47: Back to top ↑
B48: Table of Contents

Sheet 6 - Precognition (Thinking Step
B1: Chapter 6: Precognition (Thinking Step by Step)
B3: Page Contents
C4: Lesson
C5: Examples
C6: Example Playground
B8: Lesson | E8: Back to top ↑
B9: If someone woke you up and immediately started asking you several complicated questions that you had to respond to right away, how would you do? Probably not as good as if you were given time to think through your answer first. Guess what? Claude is the same way. Giving Claude time to think step by step sometimes makes Claude more accurate, particularly for complex tasks. However, thinking only counts when it's out loud. You cannot ask Claude to think but output only the answer - in this case, no thinking has actually occurred.
B11: Examples | E11: Back to top ↑
B12: In the movie review prompt below, it's clear to a human reader that the second sentence belies the first. But Claude takes the word "unrelated" too literally.
C14: Prompt | E14: Claude's Response
C15: User: Is this movie review sentiment positive or negative? This movie blew my mind with its freshness and originality. In totally unrelated news, I have been living under a rock since the year 1900. | D15: ➤ | E15: =claudeMessages(C15, 'Tutorial How-To'!$E$37,"temperature",0) -> #NAME?
B17: To improve Claude's response, let's allow Claude to think things out first before answering. We do that by literally spelling out the steps that Claude should take in order to process and think through its task. Along with a dash of role prompting, this empowers Claude to understand the review more deeply.
C19: System Prompt | E19: Claude's Response
C20: You are a savvy reader of movie reviews. | D20: ➤ | E20: =claudeMessages(C23, 'Tutorial How-To'!$E$37,"temperature",0, "system",$C20) -> #NAME?
C22: Prompt
C23: User: Is this review sentiment positive or negative? First, write the best arguments for each side in <positive-argument> and <negative-argument> XML tags, then answer. This movie blew my mind with its freshness and originality. In totally unrelated news, I have been living under a rock since 1900.
B25: Claude is sometimes sensitive to ordering. This example is on the frontier of Claude's ability to understand nuanced text, and when we swap the order of the arguments from the previous example so that negative is first and positive is second, this changes Claude's overall assessment to positive. In most situations (but not all, confusingly enough), Claude is more likely to choose the second of two options, possibly because in its training data from the web, second options were more likely to be correct.
C27: Prompt | E27: Claude's Response
C28: User: Is this review sentiment negative or positive? First write the best arguments for each side in <negative-argument> and <positive-argument> XML tags, then answer. This movie blew my mind with its freshness and originality. Unrelatedly, I have been living under a rock since 1900. | D28: ➤ | E28: =claudeMessages(C28, 'Tutorial How-To'!$E$37,"temperature",0, "system", "You are a savvy reader of movie reviews.") -> #NAME?
B31: Letting Claude think can shift Claude's answer from incorrect to correct. It's that simple in many cases where Claude makes mistakes! Let's go through an example where Claude's answer is incorrect to see how asking Claude to think can fix that.
C33: Prompt | E33: Claude's Response
